Workbook

Sheet Read me
A1: CDS-IGRL | Investment model | B1: Basis / limitations
A2: Units | B2: NGN billions unless stated. Nominal; no automatic inflation, debt, refinancing or terminal proceeds.
A3: Status | B3: ILLUSTRATIVE, NOT INVESTMENT VALIDATION. No executed guarantee, concession or tariff evidence verified.
A4: Source | B4: Investors Pitch Deck.docx, dated 15 October 2026; references below use its numbered sections.
A5: How to edit | B5: Blue font = editable input; black = formula; green = cross-sheet formula. Inputs, Streams and Funding are input tabs.
A6: Cases | B6: Headline: 35B each month; Ramp: M1–5 zero, M6–8 15B, M9–11 25B, M12 onward 35B. Downside: 60% realization and 3-month delay, both illustrative.
A7: Boundary convention | B7: Source M6–9/M9–12/M12–18 bands overlap. Non-overlapping M6–8/M9–11/M12+ adopted, not independently sourced.
A8: Funding conflict | B8: Source says first 5B and second 5B (§4); second 25B (§8); first25B+second25B (§10). Adopt illustrative 25B M0 +25B M9, not a resolved contractual schedule.
A9: Headline comparison | B9: Headline alone adopts full 50B funding M0 for like-for-like audit of source 420B proceeds. Ramp and Downside use staged funding.
A10: Revenue allocation | B10: Original seven bucket targets retained. Thirteen mutually exclusive substream allocations are illustrative, not evidence supporting 35B/month.
A11: Bottom-up | B11: Quantity × fee × events/year /1e9. Missing frequencies assumed annual and flagged. Unpriced streams =0, not invented revenue. Combined licensing/pattern quantity assigned to licensing only to avoid double count.
A12: VAT / WHT | B12: Default target revenue is VAT-exclusive; editable VAT-inclusive switch and rate. VAT is not revenue. WHT is not modeled as an expense: creditability, timing and treatment require tax advice.
... A25: Source claims | B25: 840% is gross proceeds/capital, not net ROI (740% at headline). Source ~68% IRR is not reproduced; 8.4x is MOIC, not DSCR.

Sheet Inputs
A1: Driver | B1: Value | C1: Units / source / assumption
A2: Months per year | B2: 12 | C2: Calendar convention
A3: Model months | B3: 120 | C3: Source §3: ten years
A4: Government share | B4: 0.4 | C4: Source §4/6
A5: Investor share | B5: 0.1 | C5: Source §4/6
A6: CDS legal share | B6: 0.5 | C6: Source §4/6; includes reserve and distribution
A7: OPEX reserve share | B7: 0.2 | C7: Source §4; reserve only, not actual cost
A8: CDS sweep share | B8: 0.3 | C8: Source §4; illustrative actual distribution policy
A9: VAT-inclusive target switch | B9: 0 | C9: ASSUMPTION: 0 excludes VAT from target, 1 divides target by 1+VAT rate
A10: VAT rate assumption | B10: 0.075 | C10: ILLUSTRATIVE tax parameter, not legal opinion
A11: Cash income tax rate | B11: 0.3 | C11: ILLUSTRATIVE positive monthly EBIT tax; no loss relief
A12: Staff count | B12: 800 | C12: Source §5 recruitment target; assumed fully staffed from M1
A13: Monthly cost per employee NGN | B13: 500000 | C13: UNPROVIDED assumption, fully loaded
... A35: One | B35: 1 | C35: Formula constant

Sheet Funding
A1: Use of funds | B1: B NGN | C1: Capitalized flag | D1: Source / modeling treatment
A2: Equipment | B2: 25 | C2: 1 | D2: Source §5 amount; accounting treatment illustrative
A3: Infrastructure | B3: 10 | C3: 1 | D3: Source §5 amount; accounting treatment illustrative
A4: Technology | B4: 8 | C4: 1 | D4: Source §5 amount; accounting treatment illustrative
A5: Human capital | B5: 4 | C5: 0 | D5: Source §5 amount; accounting treatment illustrative
A6: Compliance | B6: 3 | C6: 0 | D6: Source §5 amount; accounting treatment illustrative
A7: Total | B7: =SUM(B2:B6) -> 50 | C7: =SUMPRODUCT(B2:B6,C2:C6) -> 43 | D7: Capitalized total in C7
A8: Launch expense | B8: =B7-C7 -> 7

Sheet Streams
A1: Non-overlapping stream | B1: Original source bucket | C1: Bucket monthly B | D1: Illustrative allocation % | E1: Target B/month | F1: Quantity | G1: Fee NGN | H1: Events/year | I1: Bottom-up annual B | J1: Bottom-up monthly B | K1: Basis / missing evidence
A2: Pumps | B2: Oil & gas | C2: 12 | D2: 0.66666667 | E2: =C2*D2 -> 8 | F2: 20000 | G2: 100000 | H2: 4 | I2: =F2*G2*H2/Inputs!$B$32 -> 8 | J2: =I2/Inputs!$B$2 -> 0.66666667 | K2: §2: quarterly frequency explicit; allocation splits illustrative
A3: Tankers | B3: Oil & gas | C3: 12 | D3: 0.25 | E3: =C3*D3 -> 3 | F3: 10000 | G3: 200000 | H3: 1 | I3: =F3*G3*H3/Inputs!$B$32 -> 2 | J3: =I3/Inputs!$B$2 -> 0.16666667 | K3: §2: frequency UNKNOWN; annual assumed; allocation splits illustrative
A4: Depots | B4: Oil & gas | C4: 12 | D4: 0.083333333 | E4: =C4*D4 -> 1 | F4: 200 | G4: 5000000 | H4: 1 | I4: =F4*G4*H4/Inputs!$B$32 -> 1 | J4: =I4/Inputs!$B$2 -> 0.083333333 | K4: §2: frequency UNKNOWN; annual assumed; allocation splits illustrative
A5: Retail scales | B5: Retail/FMCG | C5: 6 | D5: 0.75 | E5: =C5*D5 -> 4.5 | F5: 150000 | G5: 40000 | H5: 1 | I5: =F5*G5*H5/Inputs!$B$32 -> 6 | J5: =I5/Inputs!$B$2 -> 0.5 | K5: §2: annual explicit; allocation splits illustrative
A6: Scanners | B6: Retail/FMCG | C6: 6 | D6: 0.25 | E6: =C6*D6 -> 1.5 | F6: 20000 | G6: 100000 | H6: 1 | I6: =F6*G6*H6/Inputs!$B$32 -> 2 | J6: =I6/Inputs!$B$2 -> 0.16666667 | K6: §2: frequency UNKNOWN; annual assumed; allocation splits illustrative
A7: Electricity meters | B7: Power/utilities | C7: 5 | D7: 1 | E7: =C7*D7 -> 5 | F7: 500000 | G7: 10000 | H7: 1 | I7: =F7*G7*H7/Inputs!$B$32 -> 5 | J7: =I7/Inputs!$B$2 -> 0.41666667 | K7: §2: annual explicit; allocation splits illustrative
A8: Telecom billing | B8: Telecom/banking/ICT | C8: 4 | D8: 0.625 | E8: =C8*D8 -> 2.5 | F8: 0 | G8: 0 | H8: 1 | I8: =F8*G8*H8/Inputs!$B$32 -> 0 | J8: =I8/Inputs!$B$2 -> 0 | K8: §2: no volume/fee; zero bottom-up; allocation splits illustrative
A9: Banking ICT | B9: Telecom/banking/ICT | C9: 4 | D9: 0.375 | E9: =C9*D9 -> 1.5 | F9: 0 | G9: 0 | H9: 1 | I9: =F9*G9*H9/Inputs!$B$32 -> 0 | J9: =I9/Inputs!$B$2 -> 0 | K9: §2: no volume/fee; zero bottom-up; allocation splits illustrative
A10: Manufacturing weighbridges | B10: Manufacturing | C10: 3 | D10: 1 | E10: =C10*D10 -> 3 | F10: 2000 | G10: 1500000 | H10: 1 | I10: =F10*G10*H10/Inputs!$B$32 -> 3 | J10: =I10/Inputs!$B$2 -> 0.25 | K10: §2: annual explicit; allocation splits illustrative
A11: Aviation | B11: Aviation/marine/bulk | C11: 2 | D11: 0.5 | E11: =C11*D11 -> 1 | F11: 0 | G11: 0 | H11: 1 | I11: =F11*G11*H11/Inputs!$B$32 -> 0 | J11: =I11/Inputs!$B$2 -> 0 | K11: §2: no volume/fee; zero bottom-up; airport bowsers only, excludes road tankers; allocation splits illustrative
A12: Marine | B12: Aviation/marine/bulk | C12: 2 | D12: 0.5 | E12: =C12*D12 -> 1 | F12: 0 | G12: 0 | H12: 1 | I12: =F12*G12*H12/Inputs!$B$32 -> 0 | J12: =I12/Inputs!$B$2 -> 0 | K12: §2: no volume/fee; zero bottom-up; ships/bulk marine only; allocation splits illustrative
A13: Licensing | B13: Licensing/pattern | C13: 3 | D13: 0.66666667 | E13: =C13*D13 -> 2 | F13: 5000 | G13: 600000 | H13: 1 | I13: =F13*G13*H13/Inputs!$B$32 -> 3 | J13: =I13/Inputs!$B$2 -> 0.25 | K13: §2 combined5000 assigned here only; frequency UNKNOWN annual assumed; allocation splits illustrative
A14: Pattern approval | B14: Licensing/pattern | C14: 3 | D14: 0.33333333 | E14: =C14*D14 -> 1 | F14: 0 | G14: 0 | H14: 1 | I14: =F14*G14*H14/Inputs!$B$32 -> 0 | J14: =I14/Inputs!$B$2 -> 0 | K14: §2 combined bucket; no separate priced volume; zero avoids double count; allocation splits illustrative
A15: TOTAL | E15: =SUM(E2:E14) -> 35 | I15: =SUM(I2:I14) -> 30 | J15: =SUM(J2:J14) -> 2.5
A17: Bottom-up / target | E17: =J15/E15 -> 0.071428571
A18: Unbridged target B/month | E18: =E15-J15 -> 32.5
A21: Oil & gas | B21: Allocation check =0 | E21: =SUMIF(B2:B14,A21,D2:D14)-Inputs!$B$35 -> 0
A22: Retail/FMCG | B22: Allocation check =0 | E22: =SUMIF(B2:B14,A22,D2:D14)-Inputs!$B$35 -> 0
A23: Power/utilities | B23: Allocation check =0 | E23: =SUMIF(B2:B14,A23,D2:D14)-Inputs!$B$35 -> 0
A24: Telecom/banking/ICT | B24: Allocation check =0 | E24: =SUMIF(B2:B14,A24,D2:D14)-Inputs!$B$35 -> 0
A25: Manufacturing | B25: Allocation check =0 | E25: =SUMIF(B2:B14,A25,D2:D14)-Inputs!$B$35 -> 0
A26: Aviation/marine/bulk | B26: Allocation check =0 | E26: =SUMIF(B2:B14,A26,D2:D14)-Inputs!$B$35 -> 0
A27: Licensing/pattern | B27: Allocation check =0 | E27: =SUMIF(B2:B14,A27,D2:D14)-Inputs!$B$35 -> 0

Sheet Headline
A1: Month index | B1: =Inputs!$B$34 -> 0 | C1: =B1+Inputs!$B$35 -> 1 | D1: =C1+Inputs!$B$35 -> 2 | E1: =D1+Inputs!$B$35 -> 3 | F1: =E1+Inputs!$B$35 -> 4 | G1: =F1+Inputs!$B$35 -> 5 | H1: =G1+Inputs!$B$35 -> 6 | I1: =H1+Inputs!$B$35 -> 7 | J1: =I1+Inputs!$B$35 -> 8 | ... DR1: =DQ1+Inputs!$B$35 -> 120
A2: Model year | B2: =ROUNDUP(B$1/Inputs!$B$2,Inputs!$B$34) -> 0 | C2: =ROUNDUP(C$1/Inputs!$B$2,Inputs!$B$34) -> 1 | D2: =ROUNDUP(D$1/Inputs!$B$2,Inputs!$B$34) -> 1 | E2: =ROUNDUP(E$1/Inputs!$B$2,Inputs!$B$34) -> 1 | F2: =ROUNDUP(F$1/Inputs!$B$2,Inputs!$B$34) -> 1 | G2: =ROUNDUP(G$1/Inputs!$B$2,Inputs!$B$34) -> 1 | H2: =ROUNDUP(H$1/Inputs!$B$2,Inputs!$B$34) -> 1 | I2: =ROUNDUP(I$1/Inputs!$B$2,Inputs!$B$34) -> 1 | ... DR2: =ROUNDUP(DR$1/Inputs!$B$2,Inputs!$B$34) -> 10
A3: Case target before VAT B | B3: =IF(B$1=Inputs!$B$34,Inputs!$B$34,Streams!$E$15) -> 0 | C3: =IF(C$1=Inputs!$B$34,Inputs!$B$34,Streams!$E$15) -> 35 | D3: =IF(D$1=Inputs!$B$34,Inputs!$B$34,Streams!$E$15) -> 35 | E3: =IF(E$1=Inputs!$B$34,Inputs!$B$34,Streams!$E$15) -> 35 | F3: =IF(F$1=Inputs!$B$34,Inputs!$B$34,Streams!$E$15) -> 35 | G3: =IF(G$1=Inputs!$B$34,Inputs!$B$34,Streams!$E$15) -> 35 | H3: =IF(H$1=Inputs!$B$34,Inputs!$B$34,Streams!$E$15) -> 35 | I3: =IF(I$1=Inputs!$B$34,Inputs!$B$34,Streams!$E$15) -> 35 | ... DR3: =IF(DR$1=Inputs!$B$34,Inputs!$B$34,Streams!$E$15) -> 35
A4: Revenue base excluding VAT | B4: =B3/(Inputs!$B$35+Inputs!$B$9*Inputs!$B$10) -> 0 | C4: =C3/(Inputs!$B$35+Inputs!$B$9*Inputs!$B$10) -> 35 | D4: =D3/(Inputs!$B$35+Inputs!$B$9*Inputs!$B$10) -> 35 | E4: =E3/(Inputs!$B$35+Inputs!$B$9*Inputs!$B$10) -> 35 | F4: =F3/(Inputs!$B$35+Inputs!$B$9*Inputs!$B$10) -> 35 | G4: =G3/(Inputs!$B$35+Inputs!$B$9*Inputs!$B$10) -> 35 | H4: =H3/(Inputs!$B$35+Inputs!$B$9*Inputs!$B$10) -> 35 | I4: =I3/(Inputs!$B$35+Inputs!$B$9*Inputs!$B$10) -> 35 | ... DR4: =DR3/(Inputs!$B$35+Inputs!$B$9*Inputs!$B$10) -> 35
A5: VAT excluded from base (informational) | B5: =B3-B4 -> 0 | C5: =C3-C4 -> 0 | D5: =D3-D4 -> 0 | E5: =E3-E4 -> 0 | F5: =F3-F4 -> 0 | G5: =G3-G4 -> 0 | H5: =H3-H4 -> 0 | I5: =I3-I4 -> 0 | ... DR5: =DR3-DR4 -> 0
A6: Pumps revenue | B6: =B4*Streams!$E$2/Streams!$E$15 -> 0 | C6: =C4*Streams!$E$2/Streams!$E$15 -> 8 | D6: =D4*Streams!$E$2/Streams!$E$15 -> 8 | E6: =E4*Streams!$E$2/Streams!$E$15 -> 8 | F6: =F4*Streams!$E$2/Streams!$E$15 -> 8 | G6: =G4*Streams!$E$2/Streams!$E$15 -> 8 | H6: =H4*Streams!$E$2/Streams!$E$15 -> 8 | I6: =I4*Streams!$E$2/Streams!$E$15 -> 8 | ... DR6: =DR4*Streams!$E$2/Streams!$E$15 -> 8
A7: Tankers revenue | B7: =B4*Streams!$E$3/Streams!$E$15 -> 0 | C7: =C4*Streams!$E$3/Streams!$E$15 -> 3 | D7: =D4*Streams!$E$3/Streams!$E$15 -> 3 | E7: =E4*Streams!$E$3/Streams!$E$15 -> 3 | F7: =F4*Streams!$E$3/Streams!$E$15 -> 3 | G7: =G4*Streams!$E$3/Streams!$E$15 -> 3 | H7: =H4*Streams!$E$3/Streams!$E$15 -> 3 | I7: =I4*Streams!$E$3/Streams!$E$15 -> 3 | ... DR7: =DR4*Streams!$E$3/Streams!$E$15 -> 3
A8: Depots revenue | B8: =B4*Streams!$E$4/Streams!$E$15 -> 0 | C8: =C4*Streams!$E$4/Streams!$E$15 -> 1 | D8: =D4*Streams!$E$4/Streams!$E$15 -> 1 | E8: =E4*Streams!$E$4/Streams!$E$15 -> 1 | F8: =F4*Streams!$E$4/Streams!$E$15 -> 1 | G8: =G4*Streams!$E$4/Streams!$E$15 -> 1 | H8: =H4*Streams!$E$4/Streams!$E$15 -> 1 | I8: =I4*Streams!$E$4/Streams!$E$15 -> 1 | ... DR8: =DR4*Streams!$E$4/Streams!$E$15 -> 1
A9: Retail scales revenue | B9: =B4*Streams!$E$5/Streams!$E$15 -> 0 | C9: =C4*Streams!$E$5/Streams!$E$15 -> 4.5 | D9: =D4*Streams!$E$5/Streams!$E$15 -> 4.5 | E9: =E4*Streams!$E$5/Streams!$E$15 -> 4.5 | F9: =F4*Streams!$E$5/Streams!$E$15 -> 4.5 | G9: =G4*Streams!$E$5/Streams!$E$15 -> 4.5 | H9: =H4*Streams!$E$5/Streams!$E$15 -> 4.5 | I9: =I4*Streams!$E$5/Streams!$E$15 -> 4.5 | ... DR9: =DR4*Streams!$E$5/Streams!$E$15 -> 4.5
A10: Scanners revenue | B10: =B4*Streams!$E$6/Streams!$E$15 -> 0 | C10: =C4*Streams!$E$6/Streams!$E$15 -> 1.5 | D10: =D4*Streams!$E$6/Streams!$E$15 -> 1.5 | E10: =E4*Streams!$E$6/Streams!$E$15 -> 1.5 | F10: =F4*Streams!$E$6/Streams!$E$15 -> 1.5 | G10: =G4*Streams!$E$6/Streams!$E$15 -> 1.5 | H10: =H4*Streams!$E$6/Streams!$E$15 -> 1.5 | I10: =I4*Streams!$E$6/Streams!$E$15 -> 1.5 | ... DR10: =DR4*Streams!$E$6/Streams!$E$15 -> 1.5
A11: Electricity meters revenue | B11: =B4*Streams!$E$7/Streams!$E$15 -> 0 | C11: =C4*Streams!$E$7/Streams!$E$15 -> 5 | D11: =D4*Streams!$E$7/Streams!$E$15 -> 5 | E11: =E4*Streams!$E$7/Streams!$E$15 -> 5 | F11: =F4*Streams!$E$7/Streams!$E$15 -> 5 | G11: =G4*Streams!$E$7/Streams!$E$15 -> 5 | H11: =H4*Streams!$E$7/Streams!$E$15 -> 5 | I11: =I4*Streams!$E$7/Streams!$E$15 -> 5 | ... DR11: =DR4*Streams!$E$7/Streams!$E$15 -> 5
A12: Telecom billing revenue | B12: =B4*Streams!$E$8/Streams!$E$15 -> 0 | C12: =C4*Streams!$E$8/Streams!$E$15 -> 2.5 | D12: =D4*Streams!$E$8/Streams!$E$15 -> 2.5 | E12: =E4*Streams!$E$8/Streams!$E$15 -> 2.5 | F12: =F4*Streams!$E$8/Streams!$E$15 -> 2.5 | G12: =G4*Streams!$E$8/Streams!$E$15 -> 2.5 | H12: =H4*Streams!$E$8/Streams!$E$15 -> 2.5 | I12: =I4*Streams!$E$8/Streams!$E$15 -> 2.5 | ... DR12: =DR4*Streams!$E$8/Streams!$E$15 -> 2.5
A13: Banking ICT revenue | B13: =B4*Streams!$E$9/Streams!$E$15 -> 0 | C13: =C4*Streams!$E$9/Streams!$E$15 -> 1.5 | D13: =D4*Streams!$E$9/Streams!$E$15 -> 1.5 | E13: =E4*Streams!$E$9/Streams!$E$15 -> 1.5 | F13: =F4*Streams!$E$9/Streams!$E$15 -> 1.5 | G13: =G4*Streams!$E$9/Streams!$E$15 -> 1.5 | H13: =H4*Streams!$E$9/Streams!$E$15 -> 1.5 | I13: =I4*Streams!$E$9/Streams!$E$15 -> 1.5 | ... DR13: =DR4*Streams!$E$9/Streams!$E$15 -> 1.5
A14: Manufacturing weighbridges revenue | B14: =B4*Streams!$E$10/Streams!$E$15 -> 0 | C14: =C4*Streams!$E$10/Streams!$E$15 -> 3 | D14: =D4*Streams!$E$10/Streams!$E$15 -> 3 | E14: =E4*Streams!$E$10/Streams!$E$15 -> 3 | F14: =F4*Streams!$E$10/Streams!$E$15 -> 3 | G14: =G4*Streams!$E$10/Streams!$E$15 -> 3 | H14: =H4*Streams!$E$10/Streams!$E$15 -> 3 | I14: =I4*Streams!$E$10/Streams!$E$15 -> 3 | ... DR14: =DR4*Streams!$E$10/Streams!$E$15 -> 3
A15: Aviation revenue | B15: =B4*Streams!$E$11/Streams!$E$15 -> 0 | C15: =C4*Streams!$E$11/Streams!$E$15 -> 1 | D15: =D4*Streams!$E$11/Streams!$E$15 -> 1 | E15: =E4*Streams!$E$11/Streams!$E$15 -> 1 | F15: =F4*Streams!$E$11/Streams!$E$15 -> 1 | G15: =G4*Streams!$E$11/Streams!$E$15 -> 1 | H15: =H4*Streams!$E$11/Streams!$E$15 -> 1 | I15: =I4*Streams!$E$11/Streams!$E$15 -> 1 | ... DR15: =DR4*Streams!$E$11/Streams!$E$15 -> 1
A16: Marine revenue | B16: =B4*Streams!$E$12/Streams!$E$15 -> 0 | C16: =C4*Streams!$E$12/Streams!$E$15 -> 1 | D16: =D4*Streams!$E$12/Streams!$E$15 -> 1 | E16: =E4*Streams!$E$12/Streams!$E$15 -> 1 | F16: =F4*Streams!$E$12/Streams!$E$15 -> 1 | G16: =G4*Streams!$E$12/Streams!$E$15 -> 1 | H16: =H4*Streams!$E$12/Streams!$E$15 -> 1 | I16: =I4*Streams!$E$12/Streams!$E$15 -> 1 | ... DR16: =DR4*Streams!$E$12/Streams!$E$15 -> 1
A17: Licensing revenue | B17: =B4*Streams!$E$13/Streams!$E$15 -> 0 | C17: =C4*Streams!$E$13/Streams!$E$15 -> 2 | D17: =D4*Streams!$E$13/Streams!$E$15 -> 2 | E17: =E4*Streams!$E$13/Streams!$E$15 -> 2 | F17: =F4*Streams!$E$13/Streams!$E$15 -> 2 | G17: =G4*Streams!$E$13/Streams!$E$15 -> 2 | H17: =H4*Streams!$E$13/Streams!$E$15 -> 2 | I17: =I4*Streams!$E$13/Streams!$E$15 -> 2 | ... DR17: =DR4*Streams!$E$13/Streams!$E$15 -> 2
A18: Pattern approval revenue | B18: =B4*Streams!$E$14/Streams!$E$15 -> 0 | C18: =C4*Streams!$E$14/Streams!$E$15 -> 1 | D18: =D4*Streams!$E$14/Streams!$E$15 -> 1 | E18: =E4*Streams!$E$14/Streams!$E$15 -> 1 | F18: =F4*Streams!$E$14/Streams!$E$15 -> 1 | G18: =G4*Streams!$E$14/Streams!$E$15 -> 1 | H18: =H4*Streams!$E$14/Streams!$E$15 -> 1 | I18: =I4*Streams!$E$14/Streams!$E$15 -> 1 | ... DR18: =DR4*Streams!$E$14/Streams!$E$15 -> 1
A19: Total stream revenue | B19: =SUM(B6:B18) -> 0 | C19: =SUM(C6:C18) -> 35 | D19: =SUM(D6:D18) -> 35 | E19: =SUM(E6:E18) -> 35 | F19: =SUM(F6:F18) -> 35 | G19: =SUM(G6:G18) -> 35 | H19: =SUM(H6:H18) -> 35 | I19: =SUM(I6:I18) -> 35 | ... DR19: =SUM(DR6:DR18) -> 35
A20: AR closing | B20: =B19*Inputs!$B$16/Inputs!$B$18 -> 0 | C20: =C19*Inputs!$B$16/Inputs!$B$18 -> 0 | D20: =D19*Inputs!$B$16/Inputs!$B$18 -> 0 | E20: =E19*Inputs!$B$16/Inputs!$B$18 -> 0 | F20: =F19*Inputs!$B$16/Inputs!$B$18 -> 0 | G20: =G19*Inputs!$B$16/Inputs!$B$18 -> 0 | H20: =H19*Inputs!$B$16/Inputs!$B$18 -> 0 | I20: =I19*Inputs!$B$16/Inputs!$B$18 -> 0 | ... DR20: =DR19*Inputs!$B$16/Inputs!$B$18 -> 0
A21: Change in AR | B21: =B20-Inputs!$B$34 -> 0 | C21: =C20-B20 -> 0 | D21: =D20-C20 -> 0 | E21: =E20-D20 -> 0 | F21: =F20-E20 -> 0 | G21: =G20-F20 -> 0 | H21: =H20-G20 -> 0 | I21: =I20-H20 -> 0 | J21: =J20-I20 -> 0 | ... DR21: =DR20-DQ20 -> 0
A22: Cash receipts | B22: =B19-B21 -> 0 | C22: =C19-C21 -> 35 | D22: =D19-D21 -> 35 | E22: =E19-E21 -> 35 | F22: =F19-F21 -> 35 | G22: =G19-G21 -> 35 | H22: =H19-H21 -> 35 | I22: =I19-I21 -> 35 | ... DR22: =DR19-DR21 -> 35
A23: Government allocation expense / cash paid | B23: =B19*Inputs!$B$4 -> 0 | C23: =C19*Inputs!$B$4 -> 14 | D23: =D19*Inputs!$B$4 -> 14 | E23: =E19*Inputs!$B$4 -> 14 | F23: =F19*Inputs!$B$4 -> 14 | G23: =G19*Inputs!$B$4 -> 14 | H23: =H19*Inputs!$B$4 -> 14 | I23: =I19*Inputs!$B$4 -> 14 | ... DR23: =DR19*Inputs!$B$4 -> 14
A24: Investor distribution entitlement | B24: =B22*Inputs!$B$5 -> 0 | C24: =C22*Inputs!$B$5 -> 3.5 | D24: =D22*Inputs!$B$5 -> 3.5 | E24: =E22*Inputs!$B$5 -> 3.5 | F24: =F22*Inputs!$B$5 -> 3.5 | G24: =G22*Inputs!$B$5 -> 3.5 | H24: =H22*Inputs!$B$5 -> 3.5 | I24: =I22*Inputs!$B$5 -> 3.5 | ... DR24: =DR22*Inputs!$B$5 -> 3.5
A25: CDS legal 50% of receipts (memo) | B25: =B22*Inputs!$B$6 -> 0 | C25: =C22*Inputs!$B$6 -> 17.5 | D25: =D22*Inputs!$B$6 -> 17.5 | E25: =E22*Inputs!$B$6 -> 17.5 | F25: =F22*Inputs!$B$6 -> 17.5 | G25: =G22*Inputs!$B$6 -> 17.5 | H25: =H22*Inputs!$B$6 -> 17.5 | I25: =I22*Inputs!$B$6 -> 17.5 | ... DR25: =DR22*Inputs!$B$6 -> 17.5
A26: OPEX reserve 20% receipts (memo) | B26: =B22*Inputs!$B$7 -> 0 | C26: =C22*Inputs!$B$7 -> 7 | D26: =D22*Inputs!$B$7 -> 7 | E26: =E22*Inputs!$B$7 -> 7 | F26: =F22*Inputs!$B$7 -> 7 | G26: =G22*Inputs!$B$7 -> 7 | H26: =H22*Inputs!$B$7 -> 7 | I26: =I22*Inputs!$B$7 -> 7 | ... DR26: =DR22*Inputs!$B$7 -> 7
A27: CDS distribution 30% receipts | B27: =B22*Inputs!$B$8 -> 0 | C27: =C22*Inputs!$B$8 -> 10.5 | D27: =D22*Inputs!$B$8 -> 10.5 | E27: =E22*Inputs!$B$8 -> 10.5 | F27: =F22*Inputs!$B$8 -> 10.5 | G27: =G22*Inputs!$B$8 -> 10.5 | H27: =H22*Inputs!$B$8 -> 10.5 | I27: =I22*Inputs!$B$8 -> 10.5 | ... DR27: =DR22*Inputs!$B$8 -> 10.5
A28: Personnel recurring OPEX | B28: =IF(B$1=Inputs!$B$34,Inputs!$B$34,Inputs!$B$12*Inputs!$B$13/Inputs!$B$32) -> 0 | C28: =IF(C$1=Inputs!$B$34,Inputs!$B$34,Inputs!$B$12*Inputs!$B$13/Inputs!$B$32) -> 0.4 | D28: =IF(D$1=Inputs!$B$34,Inputs!$B$34,Inputs!$B$12*Inputs!$B$13/Inputs!$B$32) -> 0.4 | E28: =IF(E$1=Inputs!$B$34,Inputs!$B$34,Inputs!$B$12*Inputs!$B$13/Inputs!$B$32) -> 0.4 | F28: =IF(F$1=Inputs!$B$34,Inputs!$B$34,Inputs!$B$12*Inputs!$B$13/Inputs!$B$32) -> 0.4 | G28: =IF(G$1=Inputs!$B$34,Inputs!$B$34,Inputs!$B$12*Inputs!$B$13/Inputs!$B$32) -> 0.4 | H28: =IF(H$1=Inputs!$B$34,Inputs!$B$34,Inputs!$B$12*Inputs!$B$13/Inputs!$B$32) -> 0.4 | I28: =IF(I$1=Inputs!$B$34,Inputs!$B$34,Inputs!$B$12*Inputs!$B$13/Inputs!$B$32) -> 0.4 | ... DR28: =IF(DR$1=Inputs!$B$34,Inputs!$B$34,Inputs!$B$12*Inputs!$B$13/Inputs!$B$32) -> 0.4
A29: Other fixed recurring OPEX | B29: =IF(B$1=Inputs!$B$34,Inputs!$B$34,Inputs!$B$14) -> 0 | C29: =IF(C$1=Inputs!$B$34,Inputs!$B$34,Inputs!$B$14) -> 0.15 | D29: =IF(D$1=Inputs!$B$34,Inputs!$B$34,Inputs!$B$14) -> 0.15 | E29: =IF(E$1=Inputs!$B$34,Inputs!$B$34,Inputs!$B$14) -> 0.15 | F29: =IF(F$1=Inputs!$B$34,Inputs!$B$34,Inputs!$B$14) -> 0.15 | G29: =IF(G$1=Inputs!$B$34,Inputs!$B$34,Inputs!$B$14) -> 0.15 | H29: =IF(H$1=Inputs!$B$34,Inputs!$B$34,Inputs!$B$14) -> 0.15 | I29: =IF(I$1=Inputs!$B$34,Inputs!$B$34,Inputs!$B$14) -> 0.15 | ... DR29: =IF(DR$1=Inputs!$B$34,Inputs!$B$34,Inputs!$B$14) -> 0.15
A30: Variable recurring OPEX | B30: =B19*Inputs!$B$15 -> 0 | C30: =C19*Inputs!$B$15 -> 2.8 | D30: =D19*Inputs!$B$15 -> 2.8 | E30: =E19*Inputs!$B$15 -> 2.8 | F30: =F19*Inputs!$B$15 -> 2.8 | G30: =G19*Inputs!$B$15 -> 2.8 | H30: =H19*Inputs!$B$15 -> 2.8 | I30: =I19*Inputs!$B$15 -> 2.8 | ... DR30: =DR19*Inputs!$B$15 -> 2.8
A31: Recurring OPEX total | B31: =SUM(B28:B30) -> 0 | C31: =SUM(C28:C30) -> 3.35 | D31: =SUM(D28:D30) -> 3.35 | E31: =SUM(E28:E30) -> 3.35 | F31: =SUM(F28:F30) -> 3.35 | G31: =SUM(G28:G30) -> 3.35 | H31: =SUM(H28:H30) -> 3.35 | I31: =SUM(I28:I30) -> 3.35 | ... DR31: =SUM(DR28:DR30) -> 3.35
A32: Launch expenses | B32: =IF(AND(B$1>Inputs!$B$34,B$1<=Inputs!$B$19),Funding!$B$8/Inputs!$B$19,Inputs!$B$34) -> 0 | C32: =IF(AND(C$1>Inputs!$B$34,C$1<=Inputs!$B$19),Funding!$B$8/Inputs!$B$19,Inputs!$B$34) -> 0.58333333 | D32: =IF(AND(D$1>Inputs!$B$34,D$1<=Inputs!$B$19),Funding!$B$8/Inputs!$B$19,Inputs!$B$34) -> 0.58333333 | E32: =IF(AND(E$1>Inputs!$B$34,E$1<=Inputs!$B$19),Funding!$B$8/Inputs!$B$19,Inputs!$B$34) -> 0.58333333 | F32: =IF(AND(F$1>Inputs!$B$34,F$1<=Inputs!$B$19),Funding!$B$8/Inputs!$B$19,Inputs!$B$34) -> 0.58333333 | G32: =IF(AND(G$1>Inputs!$B$34,G$1<=Inputs!$B$19),Funding!$B$8/Inputs!$B$19,Inputs!$B$34) -> 0.58333333 | H32: =IF(AND(H$1>Inputs!$B$34,H$1<=Inputs!$B$19),Funding!$B$8/Inputs!$B$19,Inputs!$B$34) -> 0.58333333 | I32: =IF(AND(I$1>Inputs!$B$34,I$1<=Inputs!$B$19),Funding!$B$8/Inputs!$B$19,Inputs!$B$34) -> 0.58333333 | ... DR32: =IF(AND(DR$1>Inputs!$B$34,DR$1<=Inputs!$B$19),Funding!$B$8/Inputs!$B$19,Inputs!$B$34) -> 0
A33: Total actual modeled OPEX | B33: =B31+B32 -> 0 | C33: =C31+C32 -> 3.9333333 | D33: =D31+D32 -> 3.9333333 | E33: =E31+E32 -> 3.9333333 | F33: =F31+F32 -> 3.9333333 | G33: =G31+G32 -> 3.9333333 | H33: =H31+H32 -> 3.9333333 | I33: =I31+I32 -> 3.9333333 | ... DR33: =DR31+DR32 -> 3.35
A34: Reserve less actual OPEX (memo) | B34: =B26-B33 -> 0 | C34: =C26-C33 -> 3.0666667 | D34: =D26-D33 -> 3.0666667 | E34: =E26-E33 -> 3.0666667 | F34: =F26-F33 -> 3.0666667 | G34: =G26-G33 -> 3.0666667 | H34: =H26-H33 -> 3.0666667 | I34: =I26-I33 -> 3.0666667 | ... DR34: =DR26-DR33 -> 3.65
A35: EBITDA after government allocation | B35: =B19-B23-B33 -> 0 | C35: =C19-C23-C33 -> 17.066667 | D35: =D19-D23-D33 -> 17.066667 | E35: =E19-E23-E33 -> 17.066667 | F35: =F19-F23-F33 -> 17.066667 | G35: =G19-G23-G33 -> 17.066667 | H35: =H19-H23-H33 -> 17.066667 | I35: =I19-I23-I33 -> 17.066667 | ... DR35: =DR19-DR23-DR33 -> 17.65
A36: Initial capex | B36: =IF(AND(B$1>Inputs!$B$34,B$1<=Inputs!$B$19),Funding!$C$7/Inputs!$B$19,Inputs!$B$34) -> 0 | C36: =IF(AND(C$1>Inputs!$B$34,C$1<=Inputs!$B$19),Funding!$C$7/Inputs!$B$19,Inputs!$B$34) -> 3.5833333 | D36: =IF(AND(D$1>Inputs!$B$34,D$1<=Inputs!$B$19),Funding!$C$7/Inputs!$B$19,Inputs!$B$34) -> 3.5833333 | E36: =IF(AND(E$1>Inputs!$B$34,E$1<=Inputs!$B$19),Funding!$C$7/Inputs!$B$19,Inputs!$B$34) -> 3.5833333 | F36: =IF(AND(F$1>Inputs!$B$34,F$1<=Inputs!$B$19),Funding!$C$7/Inputs!$B$19,Inputs!$B$34) -> 3.5833333 | G36: =IF(AND(G$1>Inputs!$B$34,G$1<=Inputs!$B$19),Funding!$C$7/Inputs!$B$19,Inputs!$B$34) -> 3.5833333 | H36: =IF(AND(H$1>Inputs!$B$34,H$1<=Inputs!$B$19),Funding!$C$7/Inputs!$B$19,Inputs!$B$34) -> 3.5833333 | I36: =IF(AND(I$1>Inputs!$B$34,I$1<=Inputs!$B$19),Funding!$C$7/Inputs!$B$19,Inputs!$B$34) -> 3.5833333 | ... DR36: =IF(AND(DR$1>Inputs!$B$34,DR$1<=Inputs!$B$19),Funding!$C$7/Inputs!$B$19,Inputs!$B$34) -> 0
A37: Maintenance capex | B37: =IF(B$1>Inputs!$B$19,B19*Inputs!$B$21,Inputs!$B$34) -> 0 | C37: =IF(C$1>Inputs!$B$19,C19*Inputs!$B$21,Inputs!$B$34) -> 0 | D37: =IF(D$1>Inputs!$B$19,D19*Inputs!$B$21,Inputs!$B$34) -> 0 | E37: =IF(E$1>Inputs!$B$19,E19*Inputs!$B$21,Inputs!$B$34) -> 0 | F37: =IF(F$1>Inputs!$B$19,F19*Inputs!$B$21,Inputs!$B$34) -> 0 | G37: =IF(G$1>Inputs!$B$19,G19*Inputs!$B$21,Inputs!$B$34) -> 0 | H37: =IF(H$1>Inputs!$B$19,H19*Inputs!$B$21,Inputs!$B$34) -> 0 | I37: =IF(I$1>Inputs!$B$19,I19*Inputs!$B$21,Inputs!$B$34) -> 0 | ... DR37: =IF(DR$1>Inputs!$B$19,DR19*Inputs!$B$21,Inputs!$B$34) -> 0.35
A38: Total capex | B38: =B36+B37 -> 0 | C38: =C36+C37 -> 3.5833333 | D38: =D36+D37 -> 3.5833333 | E38: =E36+E37 -> 3.5833333 | F38: =F36+F37 -> 3.5833333 | G38: =G36+G37 -> 3.5833333 | H38: =H36+H37 -> 3.5833333 | I38: =I36+I37 -> 3.5833333 | ... DR38: =DR36+DR37 -> 0.35
A39: Depreciation | B39: =SUM(INDEX($B$38:B38,Inputs!$B$35,MAX(Inputs!$B$35,COLUMN()-Inputs!$B$20)): B38)/Inputs!$B$20 -> 0 | C39: =SUM(INDEX($B$38:C38,Inputs!$B$35,MAX(Inputs!$B$35,COLUMN()-Inputs!$B$20)): C38)/Inputs!$B$20 -> 0.059722222 | D39: =SUM(INDEX($B$38:D38,Inputs!$B$35,MAX(Inputs!$B$35,COLUMN()-Inputs!$B$20)): D38)/Inputs!$B$20 -> 0.11944444 | E39: =SUM(INDEX($B$38:E38,Inputs!$B$35,MAX(Inputs!$B$35,COLUMN()-Inputs!$B$20)): E38)/Inputs!$B$20 -> 0.17916667 | F39: =SUM(INDEX($B$38:F38,Inputs!$B$35,MAX(Inputs!$B$35,COLUMN()-Inputs!$B$20)): F38)/Inputs!$B$20 -> 0.23888889 | G39: =SUM(INDEX($B$38:G38,Inputs!$B$35,MAX(Inputs!$B$35,COLUMN()-Inputs!$B$20)): G38)/Inputs!$B$20 -> 0.29861111 | H39: =SUM(INDEX($B$38:H38,Inputs!$B$35,MAX(Inputs!$B$35,COLUMN()-Inputs!$B$20)): H38)/Inputs!$B$20 -> 0.35833333 | I39: =SUM(INDEX($B$38:I38,Inputs!$B$35,MAX(Inputs!$B$35,COLUMN()-Inputs!$B$20)): I38)/Inputs!$B$20 -> 0.41805556 | ... DR39: =SUM(INDEX($B$38:DR38,Inputs!$B$35,MAX(Inputs!$B$35,COLUMN()-Inputs!$B$20)): DR38)/Inputs!$B$20 -> 0.35
A40: EBIT | B40: =B35-B39 -> 0 | C40: =C35-C39 -> 17.006944 | D40: =D35-D39 -> 16.947222 | E40: =E35-E39 -> 16.8875 | F40: =F35-F39 -> 16.827778 | G40: =G35-G39 -> 16.768056 | H40: =H35-H39 -> 16.708333 | I40: =I35-I39 -> 16.648611 | ... DR40: =DR35-DR39 -> 17.3
...

Sheet Headline annual
A1: Month index | B1: =Inputs!$B$34 -> 0 | C1: =B1+Inputs!$B$35 -> 1 | D1: =C1+Inputs!$B$35 -> 2 | E1: =D1+Inputs!$B$35 -> 3 | F1: =E1+Inputs!$B$35 -> 4 | G1: =F1+Inputs!$B$35 -> 5 | H1: =G1+Inputs!$B$35 -> 6 | I1: =H1+Inputs!$B$35 -> 7 | J1: =I1+Inputs!$B$35 -> 8 | ... L1: =K1+Inputs!$B$35 -> 10
A2: Model year | B2: =B1 -> 0 | C2: =C1 -> 1 | D2: =D1 -> 2 | E2: =E1 -> 3 | F2: =F1 -> 4 | G2: =G1 -> 5 | H2: =H1 -> 6 | I2: =I1 -> 7 | ... L2: =L1 -> 10
A3: Case target before VAT B | B3: =Headline!B3 -> 0 | C3: =SUM(Headline!C3:N3) -> 420 | D3: =SUM(Headline!O3:Z3) -> 420 | E3: =SUM(Headline!AA3:AL3) -> 420 | F3: =SUM(Headline!AM3:AX3) -> 420 | G3: =SUM(Headline!AY3:BJ3) -> 420 | H3: =SUM(Headline!BK3:BV3) -> 420 | I3: =SUM(Headline!BW3:CH3) -> 420 | J3: =SUM(Headline!CI3:CT3) -> 420 | K3: =SUM(Headline!CU3:DF3) -> 420 | L3: =SUM(Headline!DG3:DR3) -> 420
A4: Revenue base excluding VAT | B4: =Headline!B4 -> 0 | C4: =SUM(Headline!C4:N4) -> 420 | D4: =SUM(Headline!O4:Z4) -> 420 | E4: =SUM(Headline!AA4:AL4) -> 420 | F4: =SUM(Headline!AM4:AX4) -> 420 | G4: =SUM(Headline!AY4:BJ4) -> 420 | H4: =SUM(Headline!BK4:BV4) -> 420 | I4: =SUM(Headline!BW4:CH4) -> 420 | J4: =SUM(Headline!CI4:CT4) -> 420 | K4: =SUM(Headline!CU4:DF4) -> 420 | L4: =SUM(Headline!DG4:DR4) -> 420
A5: VAT excluded from base (informational) | B5: =Headline!B5 -> 0 | C5: =SUM(Headline!C5:N5) -> 0 | D5: =SUM(Headline!O5:Z5) -> 0 | E5: =SUM(Headline!AA5:AL5) -> 0 | F5: =SUM(Headline!AM5:AX5) -> 0 | G5: =SUM(Headline!AY5:BJ5) -> 0 | H5: =SUM(Headline!BK5:BV5) -> 0 | I5: =SUM(Headline!BW5:CH5) -> 0 | J5: =SUM(Headline!CI5:CT5) -> 0 | K5: =SUM(Headline!CU5:DF5) -> 0 | L5: =SUM(Headline!DG5:DR5) -> 0
A6: Pumps revenue | B6: =Headline!B6 -> 0 | C6: =SUM(Headline!C6:N6) -> 96 | D6: =SUM(Headline!O6:Z6) -> 96 | E6: =SUM(Headline!AA6:AL6) -> 96 | F6: =SUM(Headline!AM6:AX6) -> 96 | G6: =SUM(Headline!AY6:BJ6) -> 96 | H6: =SUM(Headline!BK6:BV6) -> 96 | I6: =SUM(Headline!BW6:CH6) -> 96 | J6: =SUM(Headline!CI6:CT6) -> 96 | K6: =SUM(Headline!CU6:DF6) -> 96 | L6: =SUM(Headline!DG6:DR6) -> 96
A7: Tankers revenue | B7: =Headline!B7 -> 0 | C7: =SUM(Headline!C7:N7) -> 36 | D7: =SUM(Headline!O7:Z7) -> 36 | E7: =SUM(Headline!AA7:AL7) -> 36 | F7: =SUM(Headline!AM7:AX7) -> 36 | G7: =SUM(Headline!AY7:BJ7) -> 36 | H7: =SUM(Headline!BK7:BV7) -> 36 | I7: =SUM(Headline!BW7:CH7) -> 36 | J7: =SUM(Headline!CI7:CT7) -> 36 | K7: =SUM(Headline!CU7:DF7) -> 36 | L7: =SUM(Headline!DG7:DR7) -> 36
A8: Depots revenue | B8: =Headline!B8 -> 0 | C8: =SUM(Headline!C8:N8) -> 12 | D8: =SUM(Headline!O8:Z8) -> 12 | E8: =SUM(Headline!AA8:AL8) -> 12 | F8: =SUM(Headline!AM8:AX8) -> 12 | G8: =SUM(Headline!AY8:BJ8) -> 12 | H8: =SUM(Headline!BK8:BV8) -> 12 | I8: =SUM(Headline!BW8:CH8) -> 12 | J8: =SUM(Headline!CI8:CT8) -> 12 | K8: =SUM(Headline!CU8:DF8) -> 12 | L8: =SUM(Headline!DG8:DR8) -> 12
A9: Retail scales revenue | B9: =Headline!B9 -> 0 | C9: =SUM(Headline!C9:N9) -> 54 | D9: =SUM(Headline!O9:Z9) -> 54 | E9: =SUM(Headline!AA9:AL9) -> 54 | F9: =SUM(Headline!AM9:AX9) -> 54 | G9: =SUM(Headline!AY9:BJ9) -> 54 | H9: =SUM(Headline!BK9:BV9) -> 54 | I9: =SUM(Headline!BW9:CH9) -> 54 | J9: =SUM(Headline!CI9:CT9) -> 54 | K9: =SUM(Headline!CU9:DF9) -> 54 | L9: =SUM(Headline!DG9:DR9) -> 54
A10: Scanners revenue | B10: =Headline!B10 -> 0 | C10: =SUM(Headline!C10:N10) -> 18 | D10: =SUM(Headline!O10:Z10) -> 18 | E10: =SUM(Headline!AA10:AL10) -> 18 | F10: =SUM(Headline!AM10:AX10) -> 18 | G10: =SUM(Headline!AY10:BJ10) -> 18 | H10: =SUM(Headline!BK10:BV10) -> 18 | I10: =SUM(Headline!BW10:CH10) -> 18 | J10: =SUM(Headline!CI10:CT10) -> 18 | K10: =SUM(Headline!CU10:DF10) -> 18 | L10: =SUM(Headline!DG10:DR10) -> 18
A11: Electricity meters revenue | B11: =Headline!B11 -> 0 | C11: =SUM(Headline!C11:N11) -> 60 | D11: =SUM(Headline!O11:Z11) -> 60 | E11: =SUM(Headline!AA11:AL11) -> 60 | F11: =SUM(Headline!AM11:AX11) -> 60 | G11: =SUM(Headline!AY11:BJ11) -> 60 | H11: =SUM(Headline!BK11:BV11) -> 60 | I11: =SUM(Headline!BW11:CH11) -> 60 | J11: =SUM(Headline!CI11:CT11) -> 60 | K11: =SUM(Headline!CU11:DF11) -> 60 | L11: =SUM(Headline!DG11:DR11) -> 60
A12: Telecom billing revenue | B12: =Headline!B12 -> 0 | C12: =SUM(Headline!C12:N12) -> 30 | D12: =SUM(Headline!O12:Z12) -> 30 | E12: =SUM(Headline!AA12:AL12) -> 30 | F12: =SUM(Headline!AM12:AX12) -> 30 | G12: =SUM(Headline!AY12:BJ12) -> 30 | H12: =SUM(Headline!BK12:BV12) -> 30 | I12: =SUM(Headline!BW12:CH12) -> 30 | J12: =SUM(Headline!CI12:CT12) -> 30 | K12: =SUM(Headline!CU12:DF12) -> 30 | L12: =SUM(Headline!DG12:DR12) -> 30
A13: Banking ICT revenue | B13: =Headline!B13 -> 0 | C13: =SUM(Headline!C13:N13) -> 18 | D13: =SUM(Headline!O13:Z13) -> 18 | E13: =SUM(Headline!AA13:AL13) -> 18 | F13: =SUM(Headline!AM13:AX13) -> 18 | G13: =SUM(Headline!AY13:BJ13) -> 18 | H13: =SUM(Headline!BK13:BV13) -> 18 | I13: =SUM(Headline!BW13:CH13) -> 18 | J13: =SUM(Headline!CI13:CT13) -> 18 | K13: =SUM(Headline!CU13:DF13) -> 18 | L13: =SUM(Headline!DG13:DR13) -> 18
A14: Manufacturing weighbridges revenue | B14: =Headline!B14 -> 0 | C14: =SUM(Headline!C14:N14) -> 36 | D14: =SUM(Headline!O14:Z14) -> 36 | E14: =SUM(Headline!AA14:AL14) -> 36 | F14: =SUM(Headline!AM14:AX14) -> 36 | G14: =SUM(Headline!AY14:BJ14) -> 36 | H14: =SUM(Headline!BK14:BV14) -> 36 | I14: =SUM(Headline!BW14:CH14) -> 36 | J14: =SUM(Headline!CI14:CT14) -> 36 | K14: =SUM(Headline!CU14:DF14) -> 36 | L14: =SUM(Headline!DG14:DR14) -> 36
... A19: Total stream revenue | B19: =Headline!B19 -> 0 | C19: =SUM(Headline!C19:N19) -> 420 | D19: =SUM(Headline!O19:Z19) -> 420 | E19: =SUM(Headline!AA19:AL19) -> 420 | F19: =SUM(Headline!AM19:AX19) -> 420 | G19: =SUM(Headline!AY19:BJ19) -> 420 | H19: =SUM(Headline!BK19:BV19) -> 420 | I19: =SUM(Headline!BW19:CH19) -> 420 | J19: =SUM(Headline!CI19:CT19) -> 420 | K19: =SUM(Headline!CU19:DF19) -> 420 | L19: =SUM(Headline!DG19:DR19) -> 420
A20: AR closing | B20: =Headline!B20 -> 0 | C20: =Headline!N20 -> 0 | D20: =Headline!Z20 -> 0 | E20: =Headline!AL20 -> 0 | F20: =Headline!AX20 -> 0 | G20: =Headline!BJ20 -> 0 | H20: =Headline!BV20 -> 0 | I20: =Headline!CH20 -> 0 | J20: =Headline!CT20 -> 0 | K20: =Headline!DF20 -> 0 | L20: =Headline!DR20 -> 0
A21: Change in AR | B21: =Headline!B21 -> 0 | C21: =SUM(Headline!C21:N21) -> 0 | D21: =SUM(Headline!O21:Z21) -> 0 | E21: =SUM(Headline!AA21:AL21) -> 0 | F21: =SUM(Headline!AM21:AX21) -> 0 | G21: =SUM(Headline!AY21:BJ21) -> 0 | H21: =SUM(Headline!BK21:BV21) -> 0 | I21: =SUM(Headline!BW21:CH21) -> 0 | J21: =SUM(Headline!CI21:CT21) -> 0 | K21: =SUM(Headline!CU21:DF21) -> 0 | L21: =SUM(Headline!DG21:DR21) -> 0
A22: Cash receipts | B22: =Headline!B22 -> 0 | C22: =SUM(Headline!C22:N22) -> 420 | D22: =SUM(Headline!O22:Z22) -> 420 | E22: =SUM(Headline!AA22:AL22) -> 420 | F22: =SUM(Headline!AM22:AX22) -> 420 | G22: =SUM(Headline!AY22:BJ22) -> 420 | H22: =SUM(Headline!BK22:BV22) -> 420 | I22: =SUM(Headline!BW22:CH22) -> 420 | J22: =SUM(Headline!CI22:CT22) -> 420 | K22: =SUM(Headline!CU22:DF22) -> 420 | L22: =SUM(Headline!DG22:DR22) -> 420
A23: Government allocation expense / cash paid | B23: =Headline!B23 -> 0 | C23: =SUM(Headline!C23:N23) -> 168 | D23: =SUM(Headline!O23:Z23) -> 168 | E23: =SUM(Headline!AA23:AL23) -> 168 | F23: =SUM(Headline!AM23:AX23) -> 168 | G23: =SUM(Headline!AY23:BJ23) -> 168 | H23: =SUM(Headline!BK23:BV23) -> 168 | I23: =SUM(Headline!BW23:CH23) -> 168 | J23: =SUM(Headline!CI23:CT23) -> 168 | K23: =SUM(Headline!CU23:DF23) -> 168 | L23: =SUM(Headline!DG23:DR23) -> 168
A24: Investor distribution entitlement | B24: =Headline!B24 -> 0 | C24: =SUM(Headline!C24:N24) -> 42 | D24: =SUM(Headline!O24:Z24) -> 42 | E24: =SUM(Headline!AA24:AL24) -> 42 | F24: =SUM(Headline!AM24:AX24) -> 42 | G24: =SUM(Headline!AY24:BJ24) -> 42 | H24: =SUM(Headline!BK24:BV24) -> 42 | I24: =SUM(Headline!BW24:CH24) -> 42 | J24: =SUM(Headline!CI24:CT24) -> 42 | K24: =SUM(Headline!CU24:DF24) -> 42 | L24: =SUM(Headline!DG24:DR24) -> 42
A25: CDS legal 50% of receipts (memo) | B25: =Headline!B25 -> 0 | C25: =SUM(Headline!C25:N25) -> 210 | D25: =SUM(Headline!O25:Z25) -> 210 | E25: =SUM(Headline!AA25:AL25) -> 210 | F25: =SUM(Headline!AM25:AX25) -> 210 | G25: =SUM(Headline!AY25:BJ25) -> 210 | H25: =SUM(Headline!BK25:BV25) -> 210 | I25: =SUM(Headline!BW25:CH25) -> 210 | J25: =SUM(Headline!CI25:CT25) -> 210 | K25: =SUM(Headline!CU25:DF25) -> 210 | L25: =SUM(Headline!DG25:DR25) -> 210
A26: OPEX reserve 20% receipts (memo) | B26: =Headline!B26 -> 0 | C26: =SUM(Headline!C26:N26) -> 84 | D26: =SUM(Headline!O26:Z26) -> 84 | E26: =SUM(Headline!AA26:AL26) -> 84 | F26: =SUM(Headline!AM26:AX26) -> 84 | G26: =SUM(Headline!AY26:BJ26) -> 84 | H26: =SUM(Headline!BK26:BV26) -> 84 | I26: =SUM(Headline!BW26:CH26) -> 84 | J26: =SUM(Headline!CI26:CT26) -> 84 | K26: =SUM(Headline!CU26:DF26) -> 84 | L26: =SUM(Headline!DG26:DR26) -> 84
A27: CDS distribution 30% receipts | B27: =Headline!B27 -> 0 | C27: =SUM(Headline!C27:N27) -> 126 | D27: =SUM(Headline!O27:Z27) -> 126 | E27: =SUM(Headline!AA27:AL27) -> 126 | F27: =SUM(Headline!AM27:AX27) -> 126 | G27: =SUM(Headline!AY27:BJ27) -> 126 | H27: =SUM(Headline!BK27:BV27) -> 126 | I27: =SUM(Headline!BW27:CH27) -> 126 | J27: =SUM(Headline!CI27:CT27) -> 126 | K27: =SUM(Headline!CU27:DF27) -> 126 | L27: =SUM(Headline!DG27:DR27) -> 126
A28: Personnel recurring OPEX | B28: =Headline!B28 -> 0 | C28: =SUM(Headline!C28:N28) -> 4.8 | D28: =SUM(Headline!O28:Z28) -> 4.8 | E28: =SUM(Headline!AA28:AL28) -> 4.8 | F28: =SUM(Headline!AM28:AX28) -> 4.8 | G28: =SUM(Headline!AY28:BJ28) -> 4.8 | H28: =SUM(Headline!BK28:BV28) -> 4.8 | I28: =SUM(Headline!BW28:CH28) -> 4.8 | J28: =SUM(Headline!CI28:CT28) -> 4.8 | K28: =SUM(Headline!CU28:DF28) -> 4.8 | L28: =SUM(Headline!DG28:DR28) -> 4.8
A29: Other fixed recurring OPEX | B29: =Headline!B29 -> 0 | C29: =SUM(Headline!C29:N29) -> 1.8 | D29: =SUM(Headline!O29:Z29) -> 1.8 | E29: =SUM(Headline!AA29:AL29) -> 1.8 | F29: =SUM(Headline!AM29:AX29) -> 1.8 | G29: =SUM(Headline!AY29:BJ29) -> 1.8 | H29: =SUM(Headline!BK29:BV29) -> 1.8 | I29: =SUM(Headline!BW29:CH29) -> 1.8 | J29: =SUM(Headline!CI29:CT29) -> 1.8 | K29: =SUM(Headline!CU29:DF29) -> 1.8 | L29: =SUM(Headline!DG29:DR29) -> 1.8
A30: Variable recurring OPEX | B30: =Headline!B30 -> 0 | C30: =SUM(Headline!C30:N30) -> 33.6 | D30: =SUM(Headline!O30:Z30) -> 33.6 | E30: =SUM(Headline!AA30:AL30) -> 33.6 | F30: =SUM(Headline!AM30:AX30) -> 33.6 | G30: =SUM(Headline!AY30:BJ30) -> 33.6 | H30: =SUM(Headline!BK30:BV30) -> 33.6 | I30: =SUM(Headline!BW30:CH30) -> 33.6 | J30: =SUM(Headline!CI30:CT30) -> 33.6 | K30: =SUM(Headline!CU30:DF30) -> 33.6 | L30: =SUM(Headline!DG30:DR30) -> 33.6
A31: Recurring OPEX total | B31: =Headline!B31 -> 0 | C31: =SUM(Headline!C31:N31) -> 40.2 | D31: =SUM(Headline!O31:Z31) -> 40.2 | E31: =SUM(Headline!AA31:AL31) -> 40.2 | F31: =SUM(Headline!AM31:AX31) -> 40.2 | G31: =SUM(Headline!AY31:BJ31) -> 40.2 | H31: =SUM(Headline!BK31:BV31) -> 40.2 | I31: =SUM(Headline!BW31:CH31) -> 40.2 | J31: =SUM(Headline!CI31:CT31) -> 40.2 | K31: =SUM(Headline!CU31:DF31) -> 40.2 | L31: =SUM(Headline!DG31:DR31) -> 40.2
A32: Launch expenses | B32: =Headline!B32 -> 0 | C32: =SUM(Headline!C32:N32) -> 7 | D32: =SUM(Headline!O32:Z32) -> 0 | E32: =SUM(Headline!AA32:AL32) -> 0 | F32: =SUM(Headline!AM32:AX32) -> 0 | G32: =SUM(Headline!AY32:BJ32) -> 0 | H32: =SUM(Headline!BK32:BV32) -> 0 | I32: =SUM(Headline!BW32:CH32) -> 0 | J32: =SUM(Headline!CI32:CT32) -> 0 | K32: =SUM(Headline!CU32:DF32) -> 0 | L32: =SUM(Headline!DG32:DR32) -> 0
... A42: Net income before owner distributions | B42: =Headline!B42 -> 0 | C42: =SUM(Headline!C42:N42) -> 140.09917 | D42: =SUM(Headline!O42:Z42) -> 141.9215 | E42: =SUM(Headline!AA42:AL42) -> 141.3335 | F42: =SUM(Headline!AM42:AX42) -> 140.7455 | G42: =SUM(Headline!AY42:BJ42) -> 140.1575 | H42: =SUM(Headline!BK42:BV42) -> 142.83033 | I42: =SUM(Headline!BW42:CH42) -> 145.32 | J42: =SUM(Headline!CI42:CT42) -> 145.32 | K42: =SUM(Headline!CU42:DF42) -> 145.32 | L42: =SUM(Headline!DG42:DR42) -> 145.32
A43: AP closing | B43: =Headline!B43 -> 0 | C43: =Headline!N43 -> 0 | D43: =Headline!Z43 -> 0 | E43: =Headline!AL43 -> 0 | F43: =Headline!AX43 -> 0 | G43: =Headline!BJ43 -> 0 | H43: =Headline!BV43 -> 0 | I43: =Headline!CH43 -> 0 | J43: =Headline!CT43 -> 0 | K43: =Headline!DF43 -> 0 | L43: =Headline!DR43 -> 0
A44: Change in AP | B44: =Headline!B44 -> 0 | C44: =SUM(Headline!C44:N44) -> 0 | D44: =SUM(Headline!O44:Z44) -> 0 | E44: =SUM(Headline!AA44:AL44) -> 0 | F44: =SUM(Headline!AM44:AX44) -> 0 | G44: =SUM(Headline!AY44:BJ44) -> 0 | H44: =SUM(Headline!BK44:BV44) -> 0 | I44: =SUM(Headline!BW44:CH44) -> 0 | J44: =SUM(Headline!CI44:CT44) -> 0 | K44: =SUM(Headline!CU44:DF44) -> 0 | L44: =SUM(Headline!DG44:DR44) -> 0
A45: CFO = NI + DA - change AR + change AP | B45: =Headline!B45 -> 0 | C45: =SUM(Headline!C45:N45) -> 144.7575 | D45: =SUM(Headline!O45:Z45) -> 150.9765 | E45: =SUM(Headline!AA45:AL45) -> 151.2285 | F45: =SUM(Headline!AM45:AX45) -> 151.4805 | G45: =SUM(Headline!AY45:BJ45) -> 151.7325 | H45: =SUM(Headline!BK45:BV45) -> 150.587 | I45: =SUM(Headline!BW45:CH45) -> 149.52 | J45: =SUM(Headline!CI45:CT45) -> 149.52 | K45: =SUM(Headline!CU45:DF45) -> 149.52 | L45: =SUM(Headline!DG45:DR45) -> 149.52
A46: CFI = capex outflow | B46: =Headline!B46 -> 0 | C46: =SUM(Headline!C46:N46) -> -43 | D46: =SUM(Headline!O46:Z46) -> -4.2 | E46: =SUM(Headline!AA46:AL46) -> -4.2 | F46: =SUM(Headline!AM46:AX46) -> -4.2 | G46: =SUM(Headline!AY46:BJ46) -> -4.2 | H46: =SUM(Headline!BK46:BV46) -> -4.2 | I46: =SUM(Headline!BW46:CH46) -> -4.2 | J46: =SUM(Headline!CI46:CT46) -> -4.2 | K46: =SUM(Headline!CU46:DF46) -> -4.2 | L46: =SUM(Headline!DG46:DR46) -> -4.2
A47: Investor capital contributed | B47: =Headline!B47 -> 50 | C47: =SUM(Headline!C47:N47) -> 0 | D47: =SUM(Headline!O47:Z47) -> 0 | E47: =SUM(Headline!AA47:AL47) -> 0 | F47: =SUM(Headline!AM47:AX47) -> 0 | G47: =SUM(Headline!AY47:BJ47) -> 0 | H47: =SUM(Headline!BK47:BV47) -> 0 | I47: =SUM(Headline!BW47:CH47) -> 0 | J47: =SUM(Headline!CI47:CT47) -> 0 | K47: =SUM(Headline!CU47:DF47) -> 0 | L47: =SUM(Headline!DG47:DR47) -> 0
A48: Owner distributions (investor + CDS) | B48: =Headline!B48 -> 0 | C48: =SUM(Headline!C48:N48) -> 168 | D48: =SUM(Headline!O48:Z48) -> 168 | E48: =SUM(Headline!AA48:AL48) -> 168 | F48: =SUM(Headline!AM48:AX48) -> 168 | G48: =SUM(Headline!AY48:BJ48) -> 168 | H48: =SUM(Headline!BK48:BV48) -> 168 | I48: =SUM(Headline!BW48:CH48) -> 168 | J48: =SUM(Headline!CI48:CT48) -> 168 | K48: =SUM(Headline!CU48:DF48) -> 168 | L48: =SUM(Headline!DG48:DR48) -> 168
A49: CFF = contributions - owner distributions | B49: =Headline!B49 -> 50 | C49: =SUM(Headline!C49:N49) -> -168 | D49: =SUM(Headline!O49:Z49) -> -168 | E49: =SUM(Headline!AA49:AL49) -> -168 | F49: =SUM(Headline!AM49:AX49) -> -168 | G49: =SUM(Headline!AY49:BJ49) -> -168 | H49: =SUM(Headline!BK49:BV49) -> -168 | I49: =SUM(Headline!BW49:CH49) -> -168 | J49: =SUM(Headline!CI49:CT49) -> -168 | K49: =SUM(Headline!CU49:DF49) -> -168 | L49: =SUM(Headline!DG49:DR49) -> -168
A50: Net cash flow | B50: =Headline!B50 -> 50 | C50: =SUM(Headline!C50:N50) -> -66.2425 | D50: =SUM(Headline!O50:Z50) -> -21.2235 | E50: =SUM(Headline!AA50:AL50) -> -20.9715 | F50: =SUM(Headline!AM50:AX50) -> -20.7195 | G50: =SUM(Headline!AY50:BJ50) -> -20.4675 | H50: =SUM(Headline!BK50:BV50) -> -21.613 | I50: =SUM(Headline!BW50:CH50) -> -22.68 | J50: =SUM(Headline!CI50:CT50) -> -22.68 | K50: =SUM(Headline!CU50:DF50) -> -22.68 | L50: =SUM(Headline!DG50:DR50) -> -22.68
A51: Opening unfinanced cash | B51: =Headline!B51 -> 0 | C51: =Headline!C51 -> 50 | D51: =Headline!O51 -> -16.2425 | E51: =Headline!AA51 -> -37.466 | F51: =Headline!AM51 -> -58.4375 | G51: =Headline!AY51 -> -79.157 | H51: =Headline!BK51 -> -99.6245 | I51: =Headline!BW51 -> -121.2375 | J51: =Headline!CI51 -> -143.9175 | K51: =Headline!CU51 -> -166.5975 | L51: =Headline!DG51 -> -189.2775
A52: Closing unfinanced cash | B52: =Headline!B52 -> 50 | C52: =Headline!N52 -> -16.2425 | D52: =Headline!Z52 -> -37.466 | E52: =Headline!AL52 -> -58.4375 | F52: =Headline!AX52 -> -79.157 | G52: =Headline!BJ52 -> -99.6245 | H52: =Headline!BV52 -> -121.2375 | I52: =Headline!CH52 -> -143.9175 | J52: =Headline!CT52 -> -166.5975 | K52: =Headline!DF52 -> -189.2775 | L52: =Headline!DR52 -> -211.9575
A53: Funding gap at period end | B53: =Headline!B53 -> 0 | C53: =Headline!N53 -> 16.2425 | D53: =Headline!Z53 -> 37.466 | E53: =Headline!AL53 -> 58.4375 | F53: =Headline!AX53 -> 79.157 | G53: =Headline!BJ53 -> 99.6245 | H53: =Headline!BV53 -> 121.2375 | I53: =Headline!CH53 -> 143.9175 | J53: =Headline!CT53 -> 166.5975 | K53: =Headline!DF53 -> 189.2775 | L53: =Headline!DR53 -> 211.9575
...

Sheet Ramp
A1: Month index | B1: =Inputs!$B$34 -> 0 | C1: =B1+Inputs!$B$35 -> 1 | D1: =C1+Inputs!$B$35 -> 2 | E1: =D1+Inputs!$B$35 -> 3 | F1: =E1+Inputs!$B$35 -> 4 | G1: =F1+Inputs!$B$35 -> 5 | H1: =G1+Inputs!$B$35 -> 6 | I1: =H1+Inputs!$B$35 -> 7 | J1: =I1+Inputs!$B$35 -> 8 | ... DR1: =DQ1+Inputs!$B$35 -> 120
A2: Model year | B2: =ROUNDUP(B$1/Inputs!$B$2,Inputs!$B$34) -> 0 | C2: =ROUNDUP(C$1/Inputs!$B$2,Inputs!$B$34) -> 1 | D2: =ROUNDUP(D$1/Inputs!$B$2,Inputs!$B$34) -> 1 | E2: =ROUNDUP(E$1/Inputs!$B$2,Inputs!$B$34) -> 1 | F2: =ROUNDUP(F$1/Inputs!$B$2,Inputs!$B$34) -> 1 | G2: =ROUNDUP(G$1/Inputs!$B$2,Inputs!$B$34) -> 1 | H2: =ROUNDUP(H$1/Inputs!$B$2,Inputs!$B$34) -> 1 | I2: =ROUNDUP(I$1/Inputs!$B$2,Inputs!$B$34) -> 1 | ... DR2: =ROUNDUP(DR$1/Inputs!$B$2,Inputs!$B$34) -> 10
A3: Case target before VAT B | B3: =IF(B$1=Inputs!$B$34,Inputs!$B$34,IF(B$1<Inputs!$B$25,Inputs!$B$34,IF(B$1<Inputs!$B$26,Inputs!$B$28,IF(B$1<Inputs!$B$27,Inputs!$B$29,Streams!$E$15)))) -> 0 | C3: =IF(C$1=Inputs!$B$34,Inputs!$B$34,IF(C$1<Inputs!$B$25,Inputs!$B$34,IF(C$1<Inputs!$B$26,Inputs!$B$28,IF(C$1<Inputs!$B$27,Inputs!$B$29,Streams!$E$15)))) -> 0 | D3: =IF(D$1=Inputs!$B$34,Inputs!$B$34,IF(D$1<Inputs!$B$25,Inputs!$B$34,IF(D$1<Inputs!$B$26,Inputs!$B$28,IF(D$1<Inputs!$B$27,Inputs!$B$29,Streams!$E$15)))) -> 0 | E3: =IF(E$1=Inputs!$B$34,Inputs!$B$34,IF(E$1<Inputs!$B$25,Inputs!$B$34,IF(E$1<Inputs!$B$26,Inputs!$B$28,IF(E$1<Inputs!$B$27,Inputs!$B$29,Streams!$E$15)))) -> 0 | F3: =IF(F$1=Inputs!$B$34,Inputs!$B$34,IF(F$1<Inputs!$B$25,Inputs!$B$34,IF(F$1<Inputs!$B$26,Inputs!$B$28,IF(F$1<Inputs!$B$27,Inputs!$B$29,Streams!$E$15)))) -> 0 | G3: =IF(G$1=Inputs!$B$34,Inputs!$B$34,IF(G$1<Inputs!$B$25,Inputs!$B$34,IF(G$1<Inputs!$B$26,Inputs!$B$28,IF(G$1<Inputs!$B$27,Inputs!$B$29,Streams!$E$15)))) -> 0 | H3: =IF(H$1=Inputs!$B$34,Inputs!$B$34,IF(H$1<Inputs!$B$25,Inputs!$B$34,IF(H$1<Inputs!$B$26,Inputs!$B$28,IF(H$1<Inputs!$B$27,Inputs!$B$29,Streams!$E$15)))) -> 15 | I3: =IF(I$1=Inputs!$B$34,Inputs!$B$34,IF(I$1<Inputs!$B$25,Inputs!$B$34,IF(I$1<Inputs!$B$26,Inputs!$B$28,IF(I$1<Inputs!$B$27,Inputs!$B$29,Streams!$E$15)))) -> 15 | ... DR3: =IF(DR$1=Inputs!$B$34,Inputs!$B$34,IF(DR$1<Inputs!$B$25,Inputs!$B$34,IF(DR$1<Inputs!$B$26,Inputs!$B$28,IF(DR$1<Inputs!$B$27,Inputs!$B$29,Streams!$E$15)))) -> 35
A4: Revenue base excluding VAT | B4: =B3/(Inputs!$B$35+Inputs!$B$9*Inputs!$B$10) -> 0 | C4: =C3/(Inputs!$B$35+Inputs!$B$9*Inputs!$B$10) -> 0 | D4: =D3/(Inputs!$B$35+Inputs!$B$9*Inputs!$B$10) -> 0 | E4: =E3/(Inputs!$B$35+Inputs!$B$9*Inputs!$B$10) -> 0 | F4: =F3/(Inputs!$B$35+Inputs!$B$9*Inputs!$B$10) -> 0 | G4: =G3/(Inputs!$B$35+Inputs!$B$9*Inputs!$B$10) -> 0 | H4: =H3/(Inputs!$B$35+Inputs!$B$9*Inputs!$B$10) -> 15 | I4: =I3/(Inputs!$B$35+Inputs!$B$9*Inputs!$B$10) -> 15 | ... DR4: =DR3/(Inputs!$B$35+Inputs!$B$9*Inputs!$B$10) -> 35
A5: VAT excluded from base (informational) | B5: =B3-B4 -> 0 | C5: =C3-C4 -> 0 | D5: =D3-D4 -> 0 | E5: =E3-E4 -> 0 | F5: =F3-F4 -> 0 | G5: =G3-G4 -> 0 | H5: =H3-H4 -> 0 | I5: =I3-I4 -> 0 | ... DR5: =DR3-DR4 -> 0
A6: Pumps revenue | B6: =B4*Streams!$E$2/Streams!$E$15 -> 0 | C6: =C4*Streams!$E$2/Streams!$E$15 -> 0 | D6: =D4*Streams!$E$2/Streams!$E$15 -> 0 | E6: =E4*Streams!$E$2/Streams!$E$15 -> 0 | F6: =F4*Streams!$E$2/Streams!$E$15 -> 0 | G6: =G4*Streams!$E$2/Streams!$E$15 -> 0 | H6: =H4*Streams!$E$2/Streams!$E$15 -> 3.4285714 | I6: =I4*Streams!$E$2/Streams!$E$15 -> 3.4285714 | ... DR6: =DR4*Streams!$E$2/Streams!$E$15 -> 8
A7: Tankers revenue | B7: =B4*Streams!$E$3/Streams!$E$15 -> 0 | C7: =C4*Streams!$E$3/Streams!$E$15 -> 0 | D7: =D4*Streams!$E$3/Streams!$E$15 -> 0 | E7: =E4*Streams!$E$3/Streams!$E$15 -> 0 | F7: =F4*Streams!$E$3/Streams!$E$15 -> 0 | G7: =G4*Streams!$E$3/Streams!$E$15 -> 0 | H7: =H4*Streams!$E$3/Streams!$E$15 -> 1.2857143 | I7: =I4*Streams!$E$3/Streams!$E$15 -> 1.2857143 | ... DR7: =DR4*Streams!$E$3/Streams!$E$15 -> 3
A8: Depots revenue | B8: =B4*Streams!$E$4/Streams!$E$15 -> 0 | C8: =C4*Streams!$E$4/Streams!$E$15 -> 0 | D8: =D4*Streams!$E$4/Streams!$E$15 -> 0 | E8: =E4*Streams!$E$4/Streams!$E$15 -> 0 | F8: =F4*Streams!$E$4/Streams!$E$15 -> 0 | G8: =G4*Streams!$E$4/Streams!$E$15 -> 0 | H8: =H4*Streams!$E$4/Streams!$E$15 -> 0.42857143 | I8: =I4*Streams!$E$4/Streams!$E$15 -> 0.42857143 | ... DR8: =DR4*Streams!$E$4/Streams!$E$15 -> 1
A9: Retail scales revenue | B9: =B4*Streams!$E$5/Streams!$E$15 -> 0 | C9: =C4*Streams!$E$5/Streams!$E$15 -> 0 | D9: =D4*Streams!$E$5/Streams!$E$15 -> 0 | E9: =E4*Streams!$E$5/Streams!$E$15 -> 0 | F9: =F4*Streams!$E$5/Streams!$E$15 -> 0 | G9: =G4*Streams!$E$5/Streams!$E$15 -> 0 | H9: =H4*Streams!$E$5/Streams!$E$15 -> 1.9285714 | I9: =I4*Streams!$E$5/Streams!$E$15 -> 1.9285714 | ... DR9: =DR4*Streams!$E$5/Streams!$E$15 -> 4.5
A10: Scanners revenue | B10: =B4*Streams!$E$6/Streams!$E$15 -> 0 | C10: =C4*Streams!$E$6/Streams!$E$15 -> 0 | D10: =D4*Streams!$E$6/Streams!$E$15 -> 0 | E10: =E4*Streams!$E$6/Streams!$E$15 -> 0 | F10: =F4*Streams!$E$6/Streams!$E$15 -> 0 | G10: =G4*Streams!$E$6/Streams!$E$15 -> 0 | H10: =H4*Streams!$E$6/Streams!$E$15 -> 0.64285714 | I10: =I4*Streams!$E$6/Streams!$E$15 -> 0.64285714 | ... DR10: =DR4*Streams!$E$6/Streams!$E$15 -> 1.5
A11: Electricity meters revenue | B11: =B4*Streams!$E$7/Streams!$E$15 -> 0 | C11: =C4*Streams!$E$7/Streams!$E$15 -> 0 | D11: =D4*Streams!$E$7/Streams!$E$15 -> 0 | E11: =E4*Streams!$E$7/Streams!$E$15 -> 0 | F11: =F4*Streams!$E$7/Streams!$E$15 -> 0 | G11: =G4*Streams!$E$7/Streams!$E$15 -> 0 | H11: =H4*Streams!$E$7/Streams!$E$15 -> 2.1428571 | I11: =I4*Streams!$E$7/Streams!$E$15 -> 2.1428571 | ... DR11: =DR4*Streams!$E$7/Streams!$E$15 -> 5
A12: Telecom billing revenue | B12: =B4*Streams!$E$8/Streams!$E$15 -> 0 | C12: =C4*Streams!$E$8/Streams!$E$15 -> 0 | D12: =D4*Streams!$E$8/Streams!$E$15 -> 0 | E12: =E4*Streams!$E$8/Streams!$E$15 -> 0 | F12: =F4*Streams!$E$8/Streams!$E$15 -> 0 | G12: =G4*Streams!$E$8/Streams!$E$15 -> 0 | H12: =H4*Streams!$E$8/Streams!$E$15 -> 1.0714286 | I12: =I4*Streams!$E$8/Streams!$E$15 -> 1.0714286 | ... DR12: =DR4*Streams!$E$8/Streams!$E$15 -> 2.5
A13: Banking ICT revenue | B13: =B4*Streams!$E$9/Streams!$E$15 -> 0 | C13: =C4*Streams!$E$9/Streams!$E$15 -> 0 | D13: =D4*Streams!$E$9/Streams!$E$15 -> 0 | E13: =E4*Streams!$E$9/Streams!$E$15 -> 0 | F13: =F4*Streams!$E$9/Streams!$E$15 -> 0 | G13: =G4*Streams!$E$9/Streams!$E$15 -> 0 | H13: =H4*Streams!$E$9/Streams!$E$15 -> 0.64285714 | I13: =I4*Streams!$E$9/Streams!$E$15 -> 0.64285714 | ... DR13: =DR4*Streams!$E$9/Streams!$E$15 -> 1.5
A14: Manufacturing weighbridges revenue | B14: =B4*Streams!$E$10/Streams!$E$15 -> 0 | C14: =C4*Streams!$E$10/Streams!$E$15 -> 0 | D14: =D4*Streams!$E$10/Streams!$E$15 -> 0 | E14: =E4*Streams!$E$10/Streams!$E$15 -> 0 | F14: =F4*Streams!$E$10/Streams!$E$15 -> 0 | G14: =G4*Streams!$E$10/Streams!$E$15 -> 0 | H14: =H4*Streams!$E$10/Streams!$E$15 -> 1.2857143 | I14: =I4*Streams!$E$10/Streams!$E$15 -> 1.2857143 | ... DR14: =DR4*Streams!$E$10/Streams!$E$15 -> 3
A15: Aviation revenue | B15: =B4*Streams!$E$11/Streams!$E$15 -> 0 | C15: =C4*Streams!$E$11/Streams!$E$15 -> 0 | D15: =D4*Streams!$E$11/Streams!$E$15 -> 0 | E15: =E4*Streams!$E$11/Streams!$E$15 -> 0 | F15: =F4*Streams!$E$11/Streams!$E$15 -> 0 | G15: =G4*Streams!$E$11/Streams!$E$15 -> 0 | H15: =H4*Streams!$E$11/Streams!$E$15 -> 0.42857143 | I15: =I4*Streams!$E$11/Streams!$E$15 -> 0.42857143 | ... DR15: =DR4*Streams!$E$11/Streams!$E$15 -> 1
A16: Marine revenue | B16: =B4*Streams!$E$12/Streams!$E$15 -> 0 | C16: =C4*Streams!$E$12/Streams!$E$15 -> 0 | D16: =D4*Streams!$E$12/Streams!$E$15 -> 0 | E16: =E4*Streams!$E$12/Streams!$E$15 -> 0 | F16: =F4*Streams!$E$12/Streams!$E$15 -> 0 | G16: =G4*Streams!$E$12/Streams!$E$15 -> 0 | H16: =H4*Streams!$E$12/Streams!$E$15 -> 0.42857143 | I16: =I4*Streams!$E$12/Streams!$E$15 -> 0.42857143 | ... DR16: =DR4*Streams!$E$12/Streams!$E$15 -> 1
A17: Licensing revenue | B17: =B4*Streams!$E$13/Streams!$E$15 -> 0 | C17: =C4*Streams!$E$13/Streams!$E$15 -> 0 | D17: =D4*Streams!$E$13/Streams!$E$15 -> 0 | E17: =E4*Streams!$E$13/Streams!$E$15 -> 0 | F17: =F4*Streams!$E$13/Streams!$E$15 -> 0 | G17: =G4*Streams!$E$13/Streams!$E$15 -> 0 | H17: =H4*Streams!$E$13/Streams!$E$15 -> 0.85714286 | I17: =I4*Streams!$E$13/Streams!$E$15 -> 0.85714286 | ... DR17: =DR4*Streams!$E$13/Streams!$E$15 -> 2
A18: Pattern approval revenue | B18: =B4*Streams!$E$14/Streams!$E$15 -> 0 | C18: =C4*Streams!$E$14/Streams!$E$15 -> 0 | D18: =D4*Streams!$E$14/Streams!$E$15 -> 0 | E18: =E4*Streams!$E$14/Streams!$E$15 -> 0 | F18: =F4*Streams!$E$14/Streams!$E$15 -> 0 | G18: =G4*Streams!$E$14/Streams!$E$15 -> 0 | H18: =H4*Streams!$E$14/Streams!$E$15 -> 0.42857143 | I18: =I4*Streams!$E$14/Streams!$E$15 -> 0.42857143 | ... DR18: =DR4*Streams!$E$14/Streams!$E$15 -> 1
A19: Total stream revenue | B19: =SUM(B6:B18) -> 0 | C19: =SUM(C6:C18) -> 0 | D19: =SUM(D6:D18) -> 0 | E19: =SUM(E6:E18) -> 0 | F19: =SUM(F6:F18) -> 0 | G19: =SUM(G6:G18) -> 0 | H19: =SUM(H6:H18) -> 15 | I19: =SUM(I6:I18) -> 15 | ... DR19: =SUM(DR6:DR18) -> 35
A20: AR closing | B20: =B19*Inputs!$B$16/Inputs!$B$18 -> 0 | C20: =C19*Inputs!$B$16/Inputs!$B$18 -> 0 | D20: =D19*Inputs!$B$16/Inputs!$B$18 -> 0 | E20: =E19*Inputs!$B$16/Inputs!$B$18 -> 0 | F20: =F19*Inputs!$B$16/Inputs!$B$18 -> 0 | G20: =G19*Inputs!$B$16/Inputs!$B$18 -> 0 | H20: =H19*Inputs!$B$16/Inputs!$B$18 -> 0 | I20: =I19*Inputs!$B$16/Inputs!$B$18 -> 0 | ... DR20: =DR19*Inputs!$B$16/Inputs!$B$18 -> 0
A21: Change in AR | B21: =B20-Inputs!$B$34 -> 0 | C21: =C20-B20 -> 0 | D21: =D20-C20 -> 0 | E21: =E20-D20 -> 0 | F21: =F20-E20 -> 0 | G21: =G20-F20 -> 0 | H21: =H20-G20 -> 0 | I21: =I20-H20 -> 0 | J21: =J20-I20 -> 0 | ... DR21: =DR20-DQ20 -> 0
A22: Cash receipts | B22: =B19-B21 -> 0 | C22: =C19-C21 -> 0 | D22: =D19-D21 -> 0 | E22: =E19-E21 -> 0 | F22: =F19-F21 -> 0 | G22: =G19-G21 -> 0 | H22: =H19-H21 -> 15 | I22: =I19-I21 -> 15 | ... DR22: =DR19-DR21 -> 35
A23: Government allocation expense / cash paid | B23: =B19*Inputs!$B$4 -> 0 | C23: =C19*Inputs!$B$4 -> 0 | D23: =D19*Inputs!$B$4 -> 0 | E23: =E19*Inputs!$B$4 -> 0 | F23: =F19*Inputs!$B$4 -> 0 | G23: =G19*Inputs!$B$4 -> 0 | H23: =H19*Inputs!$B$4 -> 6 | I23: =I19*Inputs!$B$4 -> 6 | ... DR23: =DR19*Inputs!$B$4 -> 14
A24: Investor distribution entitlement | B24: =B22*Inputs!$B$5 -> 0 | C24: =C22*Inputs!$B$5 -> 0 | D24: =D22*Inputs!$B$5 -> 0 | E24: =E22*Inputs!$B$5 -> 0 | F24: =F22*Inputs!$B$5 -> 0 | G24: =G22*Inputs!$B$5 -> 0 | H24: =H22*Inputs!$B$5 -> 1.5 | I24: =I22*Inputs!$B$5 -> 1.5 | ... DR24: =DR22*Inputs!$B$5 -> 3.5
A25: CDS legal 50% of receipts (memo) | B25: =B22*Inputs!$B$6 -> 0 | C25: =C22*Inputs!$B$6 -> 0 | D25: =D22*Inputs!$B$6 -> 0 | E25: =E22*Inputs!$B$6 -> 0 | F25: =F22*Inputs!$B$6 -> 0 | G25: =G22*Inputs!$B$6 -> 0 | H25: =H22*Inputs!$B$6 -> 7.5 | I25: =I22*Inputs!$B$6 -> 7.5 | ... DR25: =DR22*Inputs!$B$6 -> 17.5
A26: OPEX reserve 20% receipts (memo) | B26: =B22*Inputs!$B$7 -> 0 | C26: =C22*Inputs!$B$7 -> 0 | D26: =D22*Inputs!$B$7 -> 0 | E26: =E22*Inputs!$B$7 -> 0 | F26: =F22*Inputs!$B$7 -> 0 | G26: =G22*Inputs!$B$7 -> 0 | H26: =H22*Inputs!$B$7 -> 3 | I26: =I22*Inputs!$B$7 -> 3 | ... DR26: =DR22*Inputs!$B$7 -> 7
A27: CDS distribution 30% receipts | B27: =B22*Inputs!$B$8 -> 0 | C27: =C22*Inputs!$B$8 -> 0 | D27: =D22*Inputs!$B$8 -> 0 | E27: =E22*Inputs!$B$8 -> 0 | F27: =F22*Inputs!$B$8 -> 0 | G27: =G22*Inputs!$B$8 -> 0 | H27: =H22*Inputs!$B$8 -> 4.5 | I27: =I22*Inputs!$B$8 -> 4.5 | ... DR27: =DR22*Inputs!$B$8 -> 10.5
A28: Personnel recurring OPEX | B28: =IF(B$1=Inputs!$B$34,Inputs!$B$34,Inputs!$B$12*Inputs!$B$13/Inputs!$B$32) -> 0 | C28: =IF(C$1=Inputs!$B$34,Inputs!$B$34,Inputs!$B$12*Inputs!$B$13/Inputs!$B$32) -> 0.4 | D28: =IF(D$1=Inputs!$B$34,Inputs!$B$34,Inputs!$B$12*Inputs!$B$13/Inputs!$B$32) -> 0.4 | E28: =IF(E$1=Inputs!$B$34,Inputs!$B$34,Inputs!$B$12*Inputs!$B$13/Inputs!$B$32) -> 0.4 | F28: =IF(F$1=Inputs!$B$34,Inputs!$B$34,Inputs!$B$12*Inputs!$B$13/Inputs!$B$32) -> 0.4 | G28: =IF(G$1=Inputs!$B$34,Inputs!$B$34,Inputs!$B$12*Inputs!$B$13/Inputs!$B$32) -> 0.4 | H28: =IF(H$1=Inputs!$B$34,Inputs!$B$34,Inputs!$B$12*Inputs!$B$13/Inputs!$B$32) -> 0.4 | I28: =IF(I$1=Inputs!$B$34,Inputs!$B$34,Inputs!$B$12*Inputs!$B$13/Inputs!$B$32) -> 0.4 | ... DR28: =IF(DR$1=Inputs!$B$34,Inputs!$B$34,Inputs!$B$12*Inputs!$B$13/Inputs!$B$32) -> 0.4
A29: Other fixed recurring OPEX | B29: =IF(B$1=Inputs!$B$34,Inputs!$B$34,Inputs!$B$14) -> 0 | C29: =IF(C$1=Inputs!$B$34,Inputs!$B$34,Inputs!$B$14) -> 0.15 | D29: =IF(D$1=Inputs!$B$34,Inputs!$B$34,Inputs!$B$14) -> 0.15 | E29: =IF(E$1=Inputs!$B$34,Inputs!$B$34,Inputs!$B$14) -> 0.15 | F29: =IF(F$1=Inputs!$B$34,Inputs!$B$34,Inputs!$B$14) -> 0.15 | G29: =IF(G$1=Inputs!$B$34,Inputs!$B$34,Inputs!$B$14) -> 0.15 | H29: =IF(H$1=Inputs!$B$34,Inputs!$B$34,Inputs!$B$14) -> 0.15 | I29: =IF(I$1=Inputs!$B$34,Inputs!$B$34,Inputs!$B$14) -> 0.15 | ... DR29: =IF(DR$1=Inputs!$B$34,Inputs!$B$34,Inputs!$B$14) -> 0.15
A30: Variable recurring OPEX | B30: =B19*Inputs!$B$15 -> 0 | C30: =C19*Inputs!$B$15 -> 0 | D30: =D19*Inputs!$B$15 -> 0 | E30: =E19*Inputs!$B$15 -> 0 | F30: =F19*Inputs!$B$15 -> 0 | G30: =G19*Inputs!$B$15 -> 0 | H30: =H19*Inputs!$B$15 -> 1.2 | I30: =I19*Inputs!$B$15 -> 1.2 | ... DR30: =DR19*Inputs!$B$15 -> 2.8
A31: Recurring OPEX total | B31: =SUM(B28:B30) -> 0 | C31: =SUM(C28:C30) -> 0.55 | D31: =SUM(D28:D30) -> 0.55 | E31: =SUM(E28:E30) -> 0.55 | F31: =SUM(F28:F30) -> 0.55 | G31: =SUM(G28:G30) -> 0.55 | H31: =SUM(H28:H30) -> 1.75 | I31: =SUM(I28:I30) -> 1.75 | ... DR31: =SUM(DR28:DR30) -> 3.35
A32: Launch expenses | B32: =IF(AND(B$1>Inputs!$B$34,B$1<=Inputs!$B$19),Funding!$B$8/Inputs!$B$19,Inputs!$B$34) -> 0 | C32: =IF(AND(C$1>Inputs!$B$34,C$1<=Inputs!$B$19),Funding!$B$8/Inputs!$B$19,Inputs!$B$34) -> 0.58333333 | D32: =IF(AND(D$1>Inputs!$B$34,D$1<=Inputs!$B$19),Funding!$B$8/Inputs!$B$19,Inputs!$B$34) -> 0.58333333 | E32: =IF(AND(E$1>Inputs!$B$34,E$1<=Inputs!$B$19),Funding!$B$8/Inputs!$B$19,Inputs!$B$34) -> 0.58333333 | F32: =IF(AND(F$1>Inputs!$B$34,F$1<=Inputs!$B$19),Funding!$B$8/Inputs!$B$19,Inputs!$B$34) -> 0.58333333 | G32: =IF(AND(G$1>Inputs!$B$34,G$1<=Inputs!$B$19),Funding!$B$8/Inputs!$B$19,Inputs!$B$34) -> 0.58333333 | H32: =IF(AND(H$1>Inputs!$B$34,H$1<=Inputs!$B$19),Funding!$B$8/Inputs!$B$19,Inputs!$B$34) -> 0.58333333 | I32: =IF(AND(I$1>Inputs!$B$34,I$1<=Inputs!$B$19),Funding!$B$8/Inputs!$B$19,Inputs!$B$34) -> 0.58333333 | ... DR32: =IF(AND(DR$1>Inputs!$B$34,DR$1<=Inputs!$B$19),Funding!$B$8/Inputs!$B$19,Inputs!$B$34) -> 0
A33: Total actual modeled OPEX | B33: =B31+B32 -> 0 | C33: =C31+C32 -> 1.1333333 | D33: =D31+D32 -> 1.1333333 | E33: =E31+E32 -> 1.1333333 | F33: =F31+F32 -> 1.1333333 | G33: =G31+G32 -> 1.1333333 | H33: =H31+H32 -> 2.3333333 | I33: =I31+I32 -> 2.3333333 | ... DR33: =DR31+DR32 -> 3.35
A34: Reserve less actual OPEX (memo) | B34: =B26-B33 -> 0 | C34: =C26-C33 -> -1.1333333 | D34: =D26-D33 -> -1.1333333 | E34: =E26-E33 -> -1.1333333 | F34: =F26-F33 -> -1.1333333 | G34: =G26-G33 -> -1.1333333 | H34: =H26-H33 -> 0.66666667 | I34: =I26-I33 -> 0.66666667 | ... DR34: =DR26-DR33 -> 3.65
A35: EBITDA after government allocation | B35: =B19-B23-B33 -> 0 | C35: =C19-C23-C33 -> -1.1333333 | D35: =D19-D23-D33 -> -1.1333333 | E35: =E19-E23-E33 -> -1.1333333 | F35: =F19-F23-F33 -> -1.1333333 | G35: =G19-G23-G33 -> -1.1333333 | H35: =H19-H23-H33 -> 6.6666667 | I35: =I19-I23-I33 -> 6.6666667 | ... DR35: =DR19-DR23-DR33 -> 17.65
A36: Initial capex | B36: =IF(AND(B$1>Inputs!$B$34,B$1<=Inputs!$B$19),Funding!$C$7/Inputs!$B$19,Inputs!$B$34) -> 0 | C36: =IF(AND(C$1>Inputs!$B$34,C$1<=Inputs!$B$19),Funding!$C$7/Inputs!$B$19,Inputs!$B$34) -> 3.5833333 | D36: =IF(AND(D$1>Inputs!$B$34,D$1<=Inputs!$B$19),Funding!$C$7/Inputs!$B$19,Inputs!$B$34) -> 3.5833333 | E36: =IF(AND(E$1>Inputs!$B$34,E$1<=Inputs!$B$19),Funding!$C$7/Inputs!$B$19,Inputs!$B$34) -> 3.5833333 | F36: =IF(AND(F$1>Inputs!$B$34,F$1<=Inputs!$B$19),Funding!$C$7/Inputs!$B$19,Inputs!$B$34) -> 3.5833333 | G36: =IF(AND(G$1>Inputs!$B$34,G$1<=Inputs!$B$19),Funding!$C$7/Inputs!$B$19,Inputs!$B$34) -> 3.5833333 | H36: =IF(AND(H$1>Inputs!$B$34,H$1<=Inputs!$B$19),Funding!$C$7/Inputs!$B$19,Inputs!$B$34) -> 3.5833333 | I36: =IF(AND(I$1>Inputs!$B$34,I$1<=Inputs!$B$19),Funding!$C$7/Inputs!$B$19,Inputs!$B$34) -> 3.5833333 | ... DR36: =IF(AND(DR$1>Inputs!$B$34,DR$1<=Inputs!$B$19),Funding!$C$7/Inputs!$B$19,Inputs!$B$34) -> 0
A37: Maintenance capex | B37: =IF(B$1>Inputs!$B$19,B19*Inputs!$B$21,Inputs!$B$34) -> 0 | C37: =IF(C$1>Inputs!$B$19,C19*Inputs!$B$21,Inputs!$B$34) -> 0 | D37: =IF(D$1>Inputs!$B$19,D19*Inputs!$B$21,Inputs!$B$34) -> 0 | E37: =IF(E$1>Inputs!$B$19,E19*Inputs!$B$21,Inputs!$B$34) -> 0 | F37: =IF(F$1>Inputs!$B$19,F19*Inputs!$B$21,Inputs!$B$34) -> 0 | G37: =IF(G$1>Inputs!$B$19,G19*Inputs!$B$21,Inputs!$B$34) -> 0 | H37: =IF(H$1>Inputs!$B$19,H19*Inputs!$B$21,Inputs!$B$34) -> 0 | I37: =IF(I$1>Inputs!$B$19,I19*Inputs!$B$21,Inputs!$B$34) -> 0 | ... DR37: =IF(DR$1>Inputs!$B$19,DR19*Inputs!$B$21,Inputs!$B$34) -> 0.35
A38: Total capex | B38: =B36+B37 -> 0 | C38: =C36+C37 -> 3.5833333 | D38: =D36+D37 -> 3.5833333 | E38: =E36+E37 -> 3.5833333 | F38: =F36+F37 -> 3.5833333 | G38: =G36+G37 -> 3.5833333 | H38: =H36+H37 -> 3.5833333 | I38: =I36+I37 -> 3.5833333 | ... DR38: =DR36+DR37 -> 0.35
